---
title: データパイプラインをデバッグする
description: 失敗したフロー実行のトラブルシューティング方法を学習します。
---

[データ パイプライン用のプラットフォームをセットアップする](/v3/tutorials/platform)チュートリアルでは、Prefect Cloud を使用してデータ パイプライン用のプラットフォームをセットアップしました。
このチュートリアルでは、データ パイプラインに障害が発生した場合の対処方法を学習します。

<Info>
このチュートリアルは[前回のチュートリアル](/v3/tutorials/platform)の続きから始まりますので、まずは前回のチュートリアルを完了してください。
有料のPrefect Cloudアカウントが必要です。
</Info>

## 失敗を見つける

Prefect Cloud ダッシュボードを使用して、失敗を見つけることができます。

1. Prefect Cloud にサインインします。
1. ワークスペーススイッチャーを使用して、前回のチュートリアルで作成した「ステージング」ワークスペースを開きます。
1. **Home** に移動し、**Flow Runs** セクションで赤いバーを探します。これは失敗したフロー実行を示しています。
1. 赤いバーにマウスポインターを合わせると、フロー実行の詳細（名前、デプロイメント、期間、タイムスタンプ、タグ）が表示されます。

<Note>
特定のフローのセットのみに関心がある場合は、特定のタグ (例: `team-a`) でフィルタリングできます。
</Note>

## 障害のデバッグ

1 つのフローが複数回実行されても失敗することがあります。
このような場合は、一連の実行の中で最初の失敗を調べることが有効です。

1. **Home** ページの **Flow Runs** セクションで、`data-pipeline` フローを展開します。
1. 失敗した `data-pipeline` フロー実行のリストが、新しい順に表示されています。
1. ページネーション コントロールを使用して、リストの最後の失敗（最初に発生した失敗）に移動します。
1. フロー実行の名前をクリックして、詳細ページに移動します。
1. フロー実行の詳細ページで、右側のパネルの **Logs** セクションまで下にスクロールします。
1. 次のようなエラー メッセージを探します。

+
```
File "/opt/prefect/demos/simulate_failures.py", line 12, in process_data
    raise Exception(f"Run failed")
```

`simulate_failures.py` ファイルにエラーがあるようです。
障害の原因がわかったので、次のステップは基礎となるコードを修正することです。

## コードを更新します

`simulate_failures.py` ファイルを開き、12 行目を確認します。

```python simulate_failures.py {12}
import argparse
import asyncio
from typing import Optional

from prefect import flow, task
from prefect.client.orchestration import get_client


@task
def process_data(run: int, fail_at_run: Optional[int] = None) -> bool:
    """Simulate data processing with failures"""
    
    # Simulate persistent failures
    if fail_at_run and run > fail_at_run:
        raise Exception(f"Run failed")
    
    return True

# ...
```

問題は `if` 文です。
`--fail_at_run` フラグを指定すると、フローが `fail_at_run` 回以上実行されると、例外が発生して失敗します。
この問題を修正するには、`if` 文を削除してください。
この文を追加したのは、修正の根拠を示すためです。 :)

```python simulate_failures.py
import argparse
import asyncio
from typing import Optional
from prefect import flow, task
from prefect.client.orchestration import get_client

@task
def process_data(run: int, fail_at_run: Optional[int] = None) -> bool:
    """Simulate data processing with failures"""
    
    return True

# ...
```

これで、`--fail-at-run` フラグの有無にかかわらず、すべてのフロー実行が成功するようになりました。
この新しい動作を確認するには、ステージングワークスペースに修正をデプロイしてください。

```bash
prefect cloud workspace set --workspace "<account handle>/staging"
python simulate_failures.py --fail-at-run 3
```

スクリプトが完了したら、Prefect Cloud の **Home** ページを開いて、フロー実行が失敗しなくなったことを確認してください。

これでワークスペースを切り替えて、本番環境のワークスペースで使用されているコードも更新できるようになりました。

```bash
prefect cloud workspace set --workspace "<account handle>/production"
python simulate_failures.py
```


## 次のステップ

このチュートリアルでは、Prefect Cloud を使用して、障害が発生したデータパイプラインを修正しました。
フロー実行ライフサイクル中に発生する可能性のあるさまざまな状態の詳細については、[状態の管理](/v3/develop/manage-states) を参照してください。

次に、障害が発生したときに[チームにアラートを送信する](/v3/tutorials/alerts) 方法を学習します。

<Tip>
サポートが必要ですか? Prefect 製品アドボケートとの[ミーティングを予約](https://calendly.com/prefect-experts/prefect-product-advocates?utm_campaign=prefect_docs_cloud&utm_content=prefect_docs&utm_medium=docs&utm_source=docs)して、ご質問にお答えします。
</Tip>
