フローの最終状態は、その**_戻り値_**によって決定されます。以下のルールが適用されます。

- フロー関数内で直接例外が発生した場合、フロー実行は「FAILED」とマークされます。
- フローが手動で作成した状態を返す場合、それが最終的なフロー実行の状態として使用されます。これにより、最終状態を手動で決定できます。
- フローが状態の反復可能値を返す場合、_いずれかの_「FAILED」状態が存在すると、実行は「FAILED」とマークされます。

フローがエラーなしで返される_その他の状況_では、フローは「COMPLETED」とマークされます。

<Warning>
プログラムで状態を操作すると、フロー内のタスクが失敗してもフロー実行が失敗しない状況を作成できます。
例:
```python
from prefect import flow, task 


@task 
def add_one(x):
    return x + 1


@flow 
def my_flow():
    # avoided raising an exception via `return_state=True`
    state = add_one("1", return_state=True)
    assert state.is_failed()

    # the flow function returns successfully!
    return
```

フロー関数から `state` が返された場合、実行は `FAILED` としてマークされます。

</ Warning>