---
title: Prefect Cloud のトラブルシューティング
description: Prefect Cloud の一般的な問題を特定して解決する方法を学びます。
---

## Prefect Cloud とプロキシ

プロキシは、サーバーとクライアント間のネットワークリクエストを処理します。

Prefect Cloud と通信するために、Prefect クライアントライブラリは HTTPS リクエストを発行します。

これらのリクエストは、Python ライブラリ [`httpx`](https://www.python-httpx.org/) を使用して発行されます。
`httpx` はプロキシ環境変数を尊重するため、Prefect クライアントはプロキシ経由で通信できます。

プロキシ経由の通信を有効にするには、実行環境で `HTTPS_PROXY` および `SSL_CERT_FILE` 環境変数を設定してください。

詳細については、GitHub のディスカッション「[Prefect Cloud をプロキシで使用する](https://github.com/PrefectHQ/prefect/discussions/16175)」をご覧ください。

安全な環境での送信通信のために、UI、API、認証、および現在の OCSP サーバーの URL をホワイトリストに登録する必要があります: 

- app.prefect.cloud
- api.prefect.cloud
- auth.workos.com
- api.github.com
- github.com
- ocsp.pki.goog/s/gts1d4/OxYEb8XcYmo

## API 経由の Prefect Cloud アクセス

実行環境の Prefect Cloud API キー、環境変数設定、またはアカウントログインが正しく設定されていない場合、Prefect CLI コマンドの使用、フローの実行、または Prefect Cloud でのフロー実行結果の確認時に、エラーや予期しないフロー実行結果が発生する可能性があります。

`prefect config view` CLI コマンドを使用して、実行環境が Prefect Cloud にアクセスできるように正しく設定されていることを確認してください:

```bash
$ prefect config view
PREFECT_PROFILE='cloud'
PREFECT_API_KEY='pnu_xxxxxxxxxxxxxxxxxxxxxxxxxxxxxxxxxxxx' (from profile)
PREFECT_API_URL='https://api.prefect.cloud/api/accounts/...' (from profile)
```

`PREFECT_API_URL` が `https://api.prefect.cloud/api/...` を使用するように設定されていることを確認してください。

`PREFECT_API_KEY` が有効な API キーを使用するように設定されていることを確認してください。

アクティブなワークスペースを表示または設定するには、CLI コマンド `prefect cloud workspace ls` を使用できます。

```bash
prefect cloud workspace ls
```

```shell
┏━━━━━━━━━━━━━━━━━━━━━━━━━┓
┃   Available Workspaces: ┃
┡━━━━━━━━━━━━━━━━━━━━━━━━━┩
│   g-gadflow/g-workspace │
│    * prefect/workinonit │
━━━━━━━━━━━━━━━━━━━━━━━━━━━
    * active workspace
```

また、`PREFECT_API_URL` の URL に指定されているアカウント ID とワークスペース ID が、Prefect Cloud ワークスペースの URL に表示されているものと一致していることを確認することもできます。

## Prefect Cloud ログインエラー

Prefect Cloud へのログインに問題がある場合は、以下のトラブルシューティング手順で問題が解決するか、サポートチャネルにケースを共有する際に詳細情報が得られる可能性があります。

- Prefect Cloud 3 にログインしていますか？Prefect Cloud 1、Prefect Cloud 2、Prefect Cloud 3 はそれぞれ別のアカウントを使用します。
Prefect Cloud 3 の正しい URL を使用してください: \<https://app.prefect.cloud/>
- 既に Prefect Cloud アカウントをお持ちですか？
招待を承認できない場合は、まず招待に関連付けられたメールアドレスを使用してアカウントを作成し、その後招待を承認してください。
- シングルサインオン (SSO) プロバイダー、ソーシャル認証 (Google、Microsoft、GitHub)、またはメールに記載されたリンクのみを使用していますか？

ログインに関するその他のヒント：

- Cmd+Shift+R でブラウザを強制的にリフレッシュしてください。
- 別のブラウザでお試しください。以下のブラウザでテストを実施しています:
  - Chrome
  - Edge
  - Firefox
  - Safari
- 最近のブラウザ履歴/Cookieを消去する

どれもうまくいかなかった場合は？

\<help@prefect.io> までメールでお問い合わせください。
上記の質問への回答をメールにご記入いただくと、トラブルシューティングとブロック解除が迅速化されます。ログイン時に使用したメールアドレス、Prefect Cloud アカウント名、そして該当する場合は所属組織名も必ずご記入ください。

# 一般的なトラブルシューティング

トラブルシューティングの最初のステップは、Prefect の最新バージョンを実行していることを確認することです。
最新バージョンでない場合は、問題が既に修正されている可能性があるため、最新バージョンにアップグレードしてください（下記参照）。
さらに、エラーにはいくつかの種類があります。

* 問題はフローコードにある可能性があります。その場合は、[ログ](#logs) をよく読んでください。
* 問題は認証方法と [クラウド](#cloud) への接続の有無にある可能性があります。
* 問題はコードの[実行](#execution) 方法に関係している可能性があります。

## アップグレード

Prefect は、新機能の追加やバグ修正によって常に進化しています。
すでにパッチが特定されリリースされている場合があります。
同様の報告がないか、既存の [issues](https://github.com/PrefectHQ/prefect/issues) を検索し、[リリースノート](https://github.com/PrefectHQ/prefect/releases) をご確認ください。

以下のコマンドで最新バージョンにアップグレードしてください。

```bash
pip install --upgrade prefect
```

コンポーネントによって、Prefect の異なるバージョンが使用される場合があります。

- **Cloud** は通常最新バージョンです。Cloud は Prefect チームによって継続的にデプロイされます。
セルフホスト型サーバーを使用する場合、このバージョンを制御できます。
- **Worker** のバージョンは頻繁に変更されず、通常は作成時に最新バージョンになります。
Worker はフロー実行用のインフラストラクチャをプロビジョニングするため、アップグレードすることでインフラストラクチャの問題の解決に役立つ場合があります。
- **Flows** は、特に異なる環境で実行されている場合、作成元の Worker とは異なるバージョンを使用する場合があります。
例えば、Worker とフローの両方が最新の公式 Docker イメージを使用しているのに、Worker が 1 か月前に作成されたとします。
Worker は多くの場合、フローよりも古いバージョンです。

<Note>
**統合バージョン**

[統合](/integrations/) は、コア Prefect ライブラリとは独立してバージョン管理され、リリースされます。
コアライブラリと同じ方法で、同時にアップグレードする必要があります。
</Note>

## ログ

多くの場合、Prefect の [ログ](/v3/develop/logging/) には有益なスタックトレースが存在します。
**ログをよく読んで**、エラーの原因を特定し、原因を特定してください。

ログには 2 種類あります:

- **フローログとタスクログ** は常にフローにスコープが設定されます。これらは Prefect に送信され、UI で確認できます。
- **ワーカーログ** はフローにスコープが設定さておらず、フローの開始前に発生した事象に関する詳細情報が含まれている場合があります。
これらのログは通常、ワーカーが実行されている場所でのみ確認できます。

フローログとタスクログが空の場合、フローの開始を妨げているインフラストラクチャの問題が発生している可能性があります。
詳細については、ワーカーログを確認してください。

何が問題なのか明確にわからない場合は、ログレベルをデフォルトの `INFO` レベルから `DEBUG` レベルに更新してみてください。
ログレベルなどの[設定](https://reference.prefect.io/prefect/settings/)は、ワーカー環境からフロー実行環境に伝播されます。
環境変数または「prefect config set」CLIを使用して設定します。

```bash
# Using the CLI
prefect config set PREFECT_LOGGING_LEVEL=DEBUG

# Using environment variables
export PREFECT_LOGGING_LEVEL=DEBUG
```

`DEBUG` ログ レベルでは大量のログが生成されるため、問題が解決したら `INFO` に戻すことを検討してください。

## クラウド

Prefect Cloud を使用する場合、認証と承認に関する追加の懸念事項があります。
Prefect API は、ユーザーとサービスアカウント（総称してアクター）を API キーで認証します。
API キーが不足している、間違っている、または期限切れの場合、401 レスポンスが返され、「認証資格情報が無効です」という詳細が表示されます。
認証を確認するには、次のコマンドを使用します。「$PREFECT_API_KEY」は、ご使用の API キーに置き換えてください。

```bash
curl -s -H "Authorization: Bearer $PREFECT_API_KEY" "https://api.prefect.cloud/api/me/"
```

<Note>
**ユーザーとサービスアカウント**

[サービスアカウント](/v3/manage/cloud/manage-users/service-accounts/)（ボットと呼ばれることもあります）は、ワーカーやCI/CDシステムなど、Prefectとやり取りする人間以外のアクターを表します。
Prefectとやり取りするすべての人間は、ユーザーとして表されます。
ユーザーAPIキーは`pnu_`で始まり、サービスアカウントAPIキーは`pnb_`で始まります。
</Note>

アクターは[ワークスペース](/v3/manage/cloud/workspaces/)のメンバーになることができます。
アクターがメンバーではないワークスペースでアクションを実行しようとすると、404レスポンスが返されます。
アクターのワークスペースメンバーシップを確認するには、次のコマンドを使用します。

```bash
curl -s -H "Authorization: Bearer $PREFECT_API_KEY" "https://api.prefect.cloud/api/me/workspaces"
```

<Note>
**JSON のフォーマット**

Python には、JSON をフォーマットするための便利な [ツール](https://docs.python.org/3/library/json.html#module-json.tool) が付属しています。
出力をより読みやすくするには、上記のコマンドの末尾に次のコードを追加してください: `| python -m json.tool`
</Note>

アクターが作業中のワークスペースのメンバーであることを確認してください。
ワークスペース内では、アクターには特定の権限を付与する[ロール](/v3/manage/cloud/manage-users/manage-roles/)が割り当てられます。
権限が不十分な場合はエラーが発生します。たとえば、**Viewer** ロールでワーカーを起動するとエラーが発生します。

## 実行

ユーザーはフローをローカルで実行することも、ワーカーを介してリモートで実行することもできます。ローカル実行とは、通常、ユーザーが `python flow.py` などのコマンドを使用してフローを直接実行することを意味します。
リモート実行とは、通常、ワーカーが [デプロイメント](/v3/deploy/infrastructure-examples/docker/) (オプションで別のインフラストラクチャ上) を介してフローを実行することを意味します。

リモート実行では、フロー実行の作成と実行は別々に行われます。
フロー実行は、ワークプールとワークキューに割り当てられます。
フロー実行を実行するには、ワーカーがワークプールとワークキューにサブスクライブされている必要があります。サブスクライブされていない場合、フロー実行は「スケジュール済み」から「遅延」に変わります。
ワークプールとワークキューにサブスクライブされたワーカーがあることを確認してください。

ローカル実行とリモート実行では、相対インポートの扱いも異なる場合があります。
ローカル実行からリモート実行に切り替えたときにローカルインポートエラーが発生する場合は、`-m` フラグを使用してフローをローカルで実行し、動作を再現してみてください（たとえば、`python flow.py` ではなく `python -m flow`）。
`-m` の詳細については、こちらの [Stack Overflow の投稿](https://stackoverflow.com/a/62923810) をご覧ください。

## API テストで予期しない 307 Redirected が返されます。

**概要:** リクエスト URL には末尾に `/` が必要です。

特定のエンドポイントへのリクエスト時に末尾に `/` を含まないテストを記述した場合:

```python
async def test_example(client):
    response = await client.post("/my_route")
    assert response.status_code == 201
```

次のような失敗が表示されます:

```bash
E       assert 307 == 201
E        +  where 307 = <Response [307 Temporary Redirect]>.status_code
```

これを解決するには、末尾に `/` を含めます:

```python
async def test_example(client):
    response = await client.post("/my_route/")
    assert response.status_code == 201
```

注意: ネストされた URL へのリクエストでは *反対の* 動作を示す場合があり、末尾のスラッシュは必要ありません:

```python
async def test_nested_example(client):
    response = await client.post("/my_route/filter/")
    assert response.status_code == 307

    response = await client.post("/my_route/filter")
    assert response.status_code == 200
```

**参考:** [`0.22.0`](https://github.com/encode/httpx/blob/master/CHANGELOG.md#0200-13th-october-2021) の「HTTPX のリダイレクトのフォローがデフォルトで無効になりました」。

## `pytest.PytestUnraisableExceptionWarning` または `ResourceWarning`

`FlowRunner` 実装のいずれかを操作していると、次のようなエラーが発生する場合があります:

```bash
E               pytest.PytestUnraisableExceptionWarning: Exception ignored in: <ssl.SSLSocket fd=-1, family=AddressFamily.AF_INET, type=SocketKind.SOCK_STREAM, proto=0>
E
E               Traceback (most recent call last):
E                 File ".../pytest_asyncio/plugin.py", line 306, in setup
E                   res = await func(**_add_kwargs(func, kwargs, event_loop, request))
E               ResourceWarning: unclosed <ssl.SSLSocket fd=10, family=AddressFamily.AF_INET, type=SocketKind.SOCK_STREAM, proto=0, laddr=('127.0.0.1', 60605), raddr=('127.0.0.1', 6443)>

.../_pytest/unraisableexception.py:78: PytestUnraisableExceptionWarning

```

このエラーは、テストスイート（または「prefect」ライブラリコード）が何か（DockerデーモンやKubernetesクラスターなど）への接続を開き、それを閉じなかったことを示しています。

特定のテストを「PYTHONTRACEMALLOC=25 pytest ...」で再実行すると、Pythonが接続が開かれた場所のスタックトレースをより詳しく表示できるようになる場合があります。